Workbook

Sheet Eingabe
A1: Budget/Sprint Dashboard - Eingaben
A3: Projektstart | B3: 2026-03-01 | D3: Sprint-Caps
A4: Projektende | B4: 2026-05-31 | D4: SprintNr | E4: Cap (h)
A5: Start Sprint 1 | B5: 2026-03-01 | D5: 1 | E5: 80
A6: Sprintlänge (Wochen) | B6: 3 | D6: 2 | E6: 80
A7: Gesamtbudget (h) | B7: 300 | D7: 3 | E7: 80
A8: Monats-Cap (h) | B8: 90 | D8: 4 | E8: 80
A9: Sprint-Cap Default (h) | B9: 80 | D9: 5 | E9: 80
A10: Monat anzeigen (1. Tag) | B10: 2026-03-01 | D10: 6 | E10: 80
A11: Ausgewählter Tag | B11: 2026-03-15 | D11: 7 | E11: 80
D12: 8 | E12: 80
D13: 9 | E13: 80
A14: Tasks | D14: 10 | E14: 80
A15: ID | B15: Name | C15: SprintNr | D15: Stunden | E15: SprintStart | F15: SprintEnde | G15: OverlapStart | H15: OverlapEnde | I15: Arbeitstage | J15: h/AT
A16: t1 | B16: Task A | C16: 1 | D16: 80 | E16: =IF(C16="","",$B$5+(C16-1)*$B$6*7) | F16: =IF(E16="","",E16+$B$6*7-1) | G16: =IF(E16="","",MAX(E16,$B$3)) | H16: =IF(E16="","",MIN(F16,$B$4)) | I16: =IF(OR(G16="",H16="",G16>H16),0,NETWORKDAYS.INTL(G16,H16,1)) | J16: =IF(I16=0,0,D16/I16)
A17: t2 | B17: Task B | C17: 2 | D17: 80 | E17: =IF(C17="","",$B$5+(C17-1)*$B$6*7) | F17: =IF(E17="","",E17+$B$6*7-1) | G17: =IF(E17="","",MAX(E17,$B$3)) | H17: =IF(E17="","",MIN(F17,$B$4)) | I17: =IF(OR(G17="",H17="",G17>H17),0,NETWORKDAYS.INTL(G17,H17,1)) | J17: =IF(I17=0,0,D17/I17)
A18: t3 | B18: Task C | C18: 3 | D18: 80 | E18: =IF(C18="","",$B$5+(C18-1)*$B$6*7) | F18: =IF(E18="","",E18+$B$6*7-1) | G18: =IF(E18="","",MAX(E18,$B$3)) | H18: =IF(E18="","",MIN(F18,$B$4)) | I18: =IF(OR(G18="",H18="",G18>H18),0,NETWORKDAYS.INTL(G18,H18,1)) | J18: =IF(I18=0,0,D18/I18)
D19: 15 | E19: =IF(C19="","",$B$5+(C19-1)*$B$6*7) | F19: =IF(E19="","",E19+$B$6*7-1) | G19: =IF(E19="","",MAX(E19,$B$3)) | H19: =IF(E19="","",MIN(F19,$B$4)) | I19: =IF(OR(G19="",H19="",G19>H19),0,NETWORKDAYS.INTL(G19,H19,1)) | J19: =IF(I19=0,0,D19/I19)
D20: 16 | E20: =IF(C20="","",$B$5+(C20-1)*$B$6*7) | F20: =IF(E20="","",E20+$B$6*7-1) | G20: =IF(E20="","",MAX(E20,$B$3)) | H20: =IF(E20="","",MIN(F20,$B$4)) | I20: =IF(OR(G20="",H20="",G20>H20),0,NETWORKDAYS.INTL(G20,H20,1)) | J20: =IF(I20=0,0,D20/I20)
D21: 17 | E21: =IF(C21="","",$B$5+(C21-1)*$B$6*7) | F21: =IF(E21="","",E21+$B$6*7-1) | G21: =IF(E21="","",MAX(E21,$B$3)) | H21: =IF(E21="","",MIN(F21,$B$4)) | I21: =IF(OR(G21="",H21="",G21>H21),0,NETWORKDAYS.INTL(G21,H21,1)) | J21: =IF(I21=0,0,D21/I21)
D22: 18 | E22: =IF(C22="","",$B$5+(C22-1)*$B$6*7) | F22: =IF(E22="","",E22+$B$6*7-1) | G22: =IF(E22="","",MAX(E22,$B$3)) | H22: =IF(E22="","",MIN(F22,$B$4)) | I22: =IF(OR(G22="",H22="",G22>H22),0,NETWORKDAYS.INTL(G22,H22,1)) | J22: =IF(I22=0,0,D22/I22)
D23: 19 | E23: =IF(C23="","",$B$5+(C23-1)*$B$6*7) | F23: =IF(E23="","",E23+$B$6*7-1) | G23: =IF(E23="","",MAX(E23,$B$3)) | H23: =IF(E23="","",MIN(F23,$B$4)) | I23: =IF(OR(G23="",H23="",G23>H23),0,NETWORKDAYS.INTL(G23,H23,1)) | J23: =IF(I23=0,0,D23/I23)
D24: 20 | E24: =IF(C24="","",$B$5+(C24-1)*$B$6*7) | F24: =IF(E24="","",E24+$B$6*7-1) | G24: =IF(E24="","",MAX(E24,$B$3)) | H24: =IF(E24="","",MIN(F24,$B$4)) | I24: =IF(OR(G24="",H24="",G24>H24),0,NETWORKDAYS.INTL(G24,H24,1)) | J24: =IF(I24=0,0,D24/I24)
D25: 21 | E25: =IF(C25="","",$B$5+(C25-1)*$B$6*7) | F25: =IF(E25="","",E25+$B$6*7-1) | G25: =IF(E25="","",MAX(E25,$B$3)) | H25: =IF(E25="","",MIN(F25,$B$4)) | I25: =IF(OR(G25="",H25="",G25>H25),0,NETWORKDAYS.INTL(G25,H25,1)) | J25: =IF(I25=0,0,D25/I25)
D26: 22 | E26: =IF(C26="","",$B$5+(C26-1)*$B$6*7) | F26: =IF(E26="","",E26+$B$6*7-1) | G26: =IF(E26="","",MAX(E26,$B$3)) | H26: =IF(E26="","",MIN(F26,$B$4)) | I26: =IF(OR(G26="",H26="",G26>H26),0,NETWORKDAYS.INTL(G26,H26,1)) | J26: =IF(I26=0,0,D26/I26)
D27: 23 | E27: =IF(C27="","",$B$5+(C27-1)*$B$6*7) | F27: =IF(E27="","",E27+$B$6*7-1) | G27: =IF(E27="","",MAX(E27,$B$3)) | H27: =IF(E27="","",MIN(F27,$B$4)) | I27: =IF(OR(G27="",H27="",G27>H27),0,NETWORKDAYS.INTL(G27,H27,1)) | J27: =IF(I27=0,0,D27/I27)
D28: 24 | E28: =IF(C28="","",$B$5+(C28-1)*$B$6*7) | F28: =IF(E28="","",E28+$B$6*7-1) | G28: =IF(E28="","",MAX(E28,$B$3)) | H28: =IF(E28="","",MIN(F28,$B$4)) | I28: =IF(OR(G28="",H28="",G28>H28),0,NETWORKDAYS.INTL(G28,H28,1)) | J28: =IF(I28=0,0,D28/I28)
D29: 25 | E29: =IF(C29="","",$B$5+(C29-1)*$B$6*7) | F29: =IF(E29="","",E29+$B$6*7-1) | G29: =IF(E29="","",MAX(E29,$B$3)) | H29: =IF(E29="","",MIN(F29,$B$4)) | I29: =IF(OR(G29="",H29="",G29>H29),0,NETWORKDAYS.INTL(G29,H29,1)) | J29: =IF(I29=0,0,D29/I29)
D30: 26 | E30: =IF(C30="","",$B$5+(C30-1)*$B$6*7) | F30: =IF(E30="","",E30+$B$6*7-1) | G30: =IF(E30="","",MAX(E30,$B$3)) | H30: =IF(E30="","",MIN(F30,$B$4)) | I30: =IF(OR(G30="",H30="",G30>H30),0,NETWORKDAYS.INTL(G30,H30,1)) | J30: =IF(I30=0,0,D30/I30)
... D44: 40 | E44: =IF(C44="","",$B$5+(C44-1)*$B$6*7) | F44: =IF(E44="","",E44+$B$6*7-1) | G44: =IF(E44="","",MAX(E44,$B$3)) | H44: =IF(E44="","",MIN(F44,$B$4)) | I44: =IF(OR(G44="",H44="",G44>H44),0,NETWORKDAYS.INTL(G44,H44,1)) | J44: =IF(I44=0,0,D44/I44)
E45: =IF(C45="","",$B$5+(C45-1)*$B$6*7) | F45: =IF(E45="","",E45+$B$6*7-1) | G45: =IF(E45="","",MAX(E45,$B$3)) | H45: =IF(E45="","",MIN(F45,$B$4)) | I45: =IF(OR(G45="",H45="",G45>H45),0,NETWORKDAYS.INTL(G45,H45,1)) | J45: =IF(I45=0,0,D45/I45)
E46: =IF(C46="","",$B$5+(C46-1)*$B$6*7) | F46: =IF(E46="","",E46+$B$6*7-1) | G46: =IF(E46="","",MAX(E46,$B$3)) | H46: =IF(E46="","",MIN(F46,$B$4)) | I46: =IF(OR(G46="",H46="",G46>H46),0,NETWORKDAYS.INTL(G46,H46,1)) | J46: =IF(I46=0,0,D46/I46)
E47: =IF(C47="","",$B$5+(C47-1)*$B$6*7) | F47: =IF(E47="","",E47+$B$6*7-1) | G47: =IF(E47="","",MAX(E47,$B$3)) | H47: =IF(E47="","",MIN(F47,$B$4)) | I47: =IF(OR(G47="",H47="",G47>H47),0,NETWORKDAYS.INTL(G47,H47,1)) | J47: =IF(I47=0,0,D47/I47)
E48: =IF(C48="","",$B$5+(C48-1)*$B$6*7) | F48: =IF(E48="","",E48+$B$6*7-1) | G48: =IF(E48="","",MAX(E48,$B$3)) | H48: =IF(E48="","",MIN(F48,$B$4)) | I48: =IF(OR(G48="",H48="",G48>H48),0,NETWORKDAYS.INTL(G48,H48,1)) | J48: =IF(I48=0,0,D48/I48)
E49: =IF(C49="","",$B$5+(C49-1)*$B$6*7) | F49: =IF(E49="","",E49+$B$6*7-1) | G49: =IF(E49="","",MAX(E49,$B$3)) | H49: =IF(E49="","",MIN(F49,$B$4)) | I49: =IF(OR(G49="",H49="",G49>H49),0,NETWORKDAYS.INTL(G49,H49,1)) | J49: =IF(I49=0,0,D49/I49)
E50: =IF(C50="","",$B$5+(C50-1)*$B$6*7) | F50: =IF(E50="","",E50+$B$6*7-1) | G50: =IF(E50="","",MAX(E50,$B$3)) | H50: =IF(E50="","",MIN(F50,$B$4)) | I50: =IF(OR(G50="",H50="",G50>H50),0,NETWORKDAYS.INTL(G50,H50,1)) | J50: =IF(I50=0,0,D50/I50)
E51: =IF(C51="","",$B$5+(C51-1)*$B$6*7) | F51: =IF(E51="","",E51+$B$6*7-1) | G51: =IF(E51="","",MAX(E51,$B$3)) | H51: =IF(E51="","",MIN(F51,$B$4)) | I51: =IF(OR(G51="",H51="",G51>H51),0,NETWORKDAYS.INTL(G51,H51,1)) | J51: =IF(I51=0,0,D51/I51)
E52: =IF(C52="","",$B$5+(C52-1)*$B$6*7) | F52: =IF(E52="","",E52+$B$6*7-1) | G52: =IF(E52="","",MAX(E52,$B$3)) | H52: =IF(E52="","",MIN(F52,$B$4)) | I52: =IF(OR(G52="",H52="",G52>H52),0,NETWORKDAYS.INTL(G52,H52,1)) | J52: =IF(I52=0,0,D52/I52)
E53: =IF(C53="","",$B$5+(C53-1)*$B$6*7) | F53: =IF(E53="","",E53+$B$6*7-1) | G53: =IF(E53="","",MAX(E53,$B$3)) | H53: =IF(E53="","",MIN(F53,$B$4)) | I53: =IF(OR(G53="",H53="",G53>H53),0,NETWORKDAYS.INTL(G53,H53,1)) | J53: =IF(I53=0,0,D53/I53)
E54: =IF(C54="","",$B$5+(C54-1)*$B$6*7) | F54: =IF(E54="","",E54+$B$6*7-1) | G54: =IF(E54="","",MAX(E54,$B$3)) | H54: =IF(E54="","",MIN(F54,$B$4)) | I54: =IF(OR(G54="",H54="",G54>H54),0,NETWORKDAYS.INTL(G54,H54,1)) | J54: =IF(I54=0,0,D54/I54)
...

Sheet DailyPlan
A1: Datum | B1: ISO | C1: Wochentag | D1: MonatKey | E1: SprintNr | F1: Geplant h | G1: Kumuliert h | H1: Rest Gesamt h | I1: Rest Monat h | J1: Sprint Cap h | K1: Rest Sprint h | L1: Status
A2: =IF(ROW()-1<=Eingabe!$B$4-Eingabe!$B$3+1,Eingabe!$B$3+ROW()-2,"") | B2: =IF(A2="","",TEXT(A2,"yyyy-mm-dd")) | C2: =IF(A2="","",TEXT(A2,"ddd")) | D2: =IF(A2="","",TEXT(A2,"yyyy-mm")) | E2: =IF(A2="","",IF(A2<Eingabe!$B$5,"",INT((A2-Eingabe!$B$5)/(Eingabe!$B$6*7))+1)) | F2: =IF(A2="","",SUMPRODUCT((Eingabe!$B$16:$B$165<>"")*(Eingabe!$J$16:$J$165)*--(A2>=Eingabe!$G$16:$G$165)*--(A2<=Eingabe!$H$16:$H$165)*--(WEEKDAY(A2,2)<=5))) | G2: =IF(A2="","",SUM($F$2:F2)) | H2: =IF(A2="","",Eingabe!$B$7-G2) | I2: =IF(A2="","",Eingabe!$B$8-SUMIFS($F$2:F2,$D$2:D2,D2)) | J2: =IF(A2="","",IF(E2="",1E+99,IFERROR(VLOOKUP(E2,Eingabe!$D$5:$E$44,2,FALSE),Eingabe!$B$9))) | K2: =IF(A2="","",IF(E2="",1E+99,J2-SUMIFS($F$2:F2,$E$2:E2,E2))) | L2: =IF(A2="","",IF(OR(H2<0,I2<0,K2<0),"UNMOEGLICH","OK"))
A3: =IF(ROW()-1<=Eingabe!$B$4-Eingabe!$B$3+1,Eingabe!$B$3+ROW()-2,"") | B3: =IF(A3="","",TEXT(A3,"yyyy-mm-dd")) | C3: =IF(A3="","",TEXT(A3,"ddd")) | D3: =IF(A3="","",TEXT(A3,"yyyy-mm")) | E3: =IF(A3="","",IF(A3<Eingabe!$B$5,"",INT((A3-Eingabe!$B$5)/(Eingabe!$B$6*7))+1)) | F3: =IF(A3="","",SUMPRODUCT((Eingabe!$B$16:$B$165<>"")*(Eingabe!$J$16:$J$165)*--(A3>=Eingabe!$G$16:$G$165)*--(A3<=Eingabe!$H$16:$H$165)*--(WEEKDAY(A3,2)<=5))) | G3: =IF(A3="","",SUM($F$2:F3)) | H3: =IF(A3="","",Eingabe!$B$7-G3) | I3: =IF(A3="","",Eingabe!$B$8-SUMIFS($F$2:F3,$D$2:D3,D3)) | J3: =IF(A3="","",IF(E3="",1E+99,IFERROR(VLOOKUP(E3,Eingabe!$D$5:$E$44,2,FALSE),Eingabe!$B$9))) | K3: =IF(A3="","",IF(E3="",1E+99,J3-SUMIFS($F$2:F3,$E$2:E3,E3))) | L3: =IF(A3="","",IF(OR(H3<0,I3<0,K3<0),"UNMOEGLICH","OK"))
A4: =IF(ROW()-1<=Eingabe!$B$4-Eingabe!$B$3+1,Eingabe!$B$3+ROW()-2,"") | B4: =IF(A4="","",TEXT(A4,"yyyy-mm-dd")) | C4: =IF(A4="","",TEXT(A4,"ddd")) | D4: =IF(A4="","",TEXT(A4,"yyyy-mm")) | E4: =IF(A4="","",IF(A4<Eingabe!$B$5,"",INT((A4-Eingabe!$B$5)/(Eingabe!$B$6*7))+1)) | F4: =IF(A4="","",SUMPRODUCT((Eingabe!$B$16:$B$165<>"")*(Eingabe!$J$16:$J$165)*--(A4>=Eingabe!$G$16:$G$165)*--(A4<=Eingabe!$H$16:$H$165)*--(WEEKDAY(A4,2)<=5))) | G4: =IF(A4="","",SUM($F$2:F4)) | H4: =IF(A4="","",Eingabe!$B$7-G4) | I4: =IF(A4="","",Eingabe!$B$8-SUMIFS($F$2:F4,$D$2:D4,D4)) | J4: =IF(A4="","",IF(E4="",1E+99,IFERROR(VLOOKUP(E4,Eingabe!$D$5:$E$44,2,FALSE),Eingabe!$B$9))) | K4: =IF(A4="","",IF(E4="",1E+99,J4-SUMIFS($F$2:F4,$E$2:E4,E4))) | L4: =IF(A4="","",IF(OR(H4<0,I4<0,K4<0),"UNMOEGLICH","OK"))
A5: =IF(ROW()-1<=Eingabe!$B$4-Eingabe!$B$3+1,Eingabe!$B$3+ROW()-2,"") | B5: =IF(A5="","",TEXT(A5,"yyyy-mm-dd")) | C5: =IF(A5="","",TEXT(A5,"ddd")) | D5: =IF(A5="","",TEXT(A5,"yyyy-mm")) | E5: =IF(A5="","",IF(A5<Eingabe!$B$5,"",INT((A5-Eingabe!$B$5)/(Eingabe!$B$6*7))+1)) | F5: =IF(A5="","",SUMPRODUCT((Eingabe!$B$16:$B$165<>"")*(Eingabe!$J$16:$J$165)*--(A5>=Eingabe!$G$16:$G$165)*--(A5<=Eingabe!$H$16:$H$165)*--(WEEKDAY(A5,2)<=5))) | G5: =IF(A5="","",SUM($F$2:F5)) | H5: =IF(A5="","",Eingabe!$B$7-G5) | I5: =IF(A5="","",Eingabe!$B$8-SUMIFS($F$2:F5,$D$2:D5,D5)) | J5: =IF(A5="","",IF(E5="",1E+99,IFERROR(VLOOKUP(E5,Eingabe!$D$5:$E$44,2,FALSE),Eingabe!$B$9))) | K5: =IF(A5="","",IF(E5="",1E+99,J5-SUMIFS($F$2:F5,$E$2:E5,E5))) | L5: =IF(A5="","",IF(OR(H5<0,I5<0,K5<0),"UNMOEGLICH","OK"))
A6: =IF(ROW()-1<=Eingabe!$B$4-Eingabe!$B$3+1,Eingabe!$B$3+ROW()-2,"") | B6: =IF(A6="","",TEXT(A6,"yyyy-mm-dd")) | C6: =IF(A6="","",TEXT(A6,"ddd")) | D6: =IF(A6="","",TEXT(A6,"yyyy-mm")) | E6: =IF(A6="","",IF(A6<Eingabe!$B$5,"",INT((A6-Eingabe!$B$5)/(Eingabe!$B$6*7))+1)) | F6: =IF(A6="","",SUMPRODUCT((Eingabe!$B$16:$B$165<>"")*(Eingabe!$J$16:$J$165)*--(A6>=Eingabe!$G$16:$G$165)*--(A6<=Eingabe!$H$16:$H$165)*--(WEEKDAY(A6,2)<=5))) | G6: =IF(A6="","",SUM($F$2:F6)) | H6: =IF(A6="","",Eingabe!$B$7-G6) | I6: =IF(A6="","",Eingabe!$B$8-SUMIFS($F$2:F6,$D$2:D6,D6)) | J6: =IF(A6="","",IF(E6="",1E+99,IFERROR(VLOOKUP(E6,Eingabe!$D$5:$E$44,2,FALSE),Eingabe!$B$9))) | K6: =IF(A6="","",IF(E6="",1E+99,J6-SUMIFS($F$2:F6,$E$2:E6,E6))) | L6: =IF(A6="","",IF(OR(H6<0,I6<0,K6<0),"UNMOEGLICH","OK"))
A7: =IF(ROW()-1<=Eingabe!$B$4-Eingabe!$B$3+1,Eingabe!$B$3+ROW()-2,"") | B7: =IF(A7="","",TEXT(A7,"yyyy-mm-dd")) | C7: =IF(A7="","",TEXT(A7,"ddd")) | D7: =IF(A7="","",TEXT(A7,"yyyy-mm")) | E7: =IF(A7="","",IF(A7<Eingabe!$B$5,"",INT((A7-Eingabe!$B$5)/(Eingabe!$B$6*7))+1)) | F7: =IF(A7="","",SUMPRODUCT((Eingabe!$B$16:$B$165<>"")*(Eingabe!$J$16:$J$165)*--(A7>=Eingabe!$G$16:$G$165)*--(A7<=Eingabe!$H$16:$H$165)*--(WEEKDAY(A7,2)<=5))) | G7: =IF(A7="","",SUM($F$2:F7)) | H7: =IF(A7="","",Eingabe!$B$7-G7) | I7: =IF(A7="","",Eingabe!$B$8-SUMIFS($F$2:F7,$D$2:D7,D7)) | J7: =IF(A7="","",IF(E7="",1E+99,IFERROR(VLOOKUP(E7,Eingabe!$D$5:$E$44,2,FALSE),Eingabe!$B$9))) | K7: =IF(A7="","",IF(E7="",1E+99,J7-SUMIFS($F$2:F7,$E$2:E7,E7))) | L7: =IF(A7="","",IF(OR(H7<0,I7<0,K7<0),"UNMOEGLICH","OK"))
A8: =IF(ROW()-1<=Eingabe!$B$4-Eingabe!$B$3+1,Eingabe!$B$3+ROW()-2,"") | B8: =IF(A8="","",TEXT(A8,"yyyy-mm-dd")) | C8: =IF(A8="","",TEXT(A8,"ddd")) | D8: =IF(A8="","",TEXT(A8,"yyyy-mm")) | E8: =IF(A8="","",IF(A8<Eingabe!$B$5,"",INT((A8-Eingabe!$B$5)/(Eingabe!$B$6*7))+1)) | F8: =IF(A8="","",SUMPRODUCT((Eingabe!$B$16:$B$165<>"")*(Eingabe!$J$16:$J$165)*--(A8>=Eingabe!$G$16:$G$165)*--(A8<=Eingabe!$H$16:$H$165)*--(WEEKDAY(A8,2)<=5))) | G8: =IF(A8="","",SUM($F$2:F8)) | H8: =IF(A8="","",Eingabe!$B$7-G8) | I8: =IF(A8="","",Eingabe!$B$8-SUMIFS($F$2:F8,$D$2:D8,D8)) | J8: =IF(A8="","",IF(E8="",1E+99,IFERROR(VLOOKUP(E8,Eingabe!$D$5:$E$44,2,FALSE),Eingabe!$B$9))) | K8: =IF(A8="","",IF(E8="",1E+99,J8-SUMIFS($F$2:F8,$E$2:E8,E8))) | L8: =IF(A8="","",IF(OR(H8<0,I8<0,K8<0),"UNMOEGLICH","OK"))
A9: =IF(ROW()-1<=Eingabe!$B$4-Eingabe!$B$3+1,Eingabe!$B$3+ROW()-2,"") | B9: =IF(A9="","",TEXT(A9,"yyyy-mm-dd")) | C9: =IF(A9="","",TEXT(A9,"ddd")) | D9: =IF(A9="","",TEXT(A9,"yyyy-mm")) | E9: =IF(A9="","",IF(A9<Eingabe!$B$5,"",INT((A9-Eingabe!$B$5)/(Eingabe!$B$6*7))+1)) | F9: =IF(A9="","",SUMPRODUCT((Eingabe!$B$16:$B$165<>"")*(Eingabe!$J$16:$J$165)*--(A9>=Eingabe!$G$16:$G$165)*--(A9<=Eingabe!$H$16:$H$165)*--(WEEKDAY(A9,2)<=5))) | G9: =IF(A9="","",SUM($F$2:F9)) | H9: =IF(A9="","",Eingabe!$B$7-G9) | I9: =IF(A9="","",Eingabe!$B$8-SUMIFS($F$2:F9,$D$2:D9,D9)) | J9: =IF(A9="","",IF(E9="",1E+99,IFERROR(VLOOKUP(E9,Eingabe!$D$5:$E$44,2,FALSE),Eingabe!$B$9))) | K9: =IF(A9="","",IF(E9="",1E+99,J9-SUMIFS($F$2:F9,$E$2:E9,E9))) | L9: =IF(A9="","",IF(OR(H9<0,I9<0,K9<0),"UNMOEGLICH","OK"))
A10: =IF(ROW()-1<=Eingabe!$B$4-Eingabe!$B$3+1,Eingabe!$B$3+ROW()-2,"") | B10: =IF(A10="","",TEXT(A10,"yyyy-mm-dd")) | C10: =IF(A10="","",TEXT(A10,"ddd")) | D10: =IF(A10="","",TEXT(A10,"yyyy-mm")) | E10: =IF(A10="","",IF(A10<Eingabe!$B$5,"",INT((A10-Eingabe!$B$5)/(Eingabe!$B$6*7))+1)) | F10: =IF(A10="","",SUMPRODUCT((Eingabe!$B$16:$B$165<>"")*(Eingabe!$J$16:$J$165)*--(A10>=Eingabe!$G$16:$G$165)*--(A10<=Eingabe!$H$16:$H$165)*--(WEEKDAY(A10,2)<=5))) | G10: =IF(A10="","",SUM($F$2:F10)) | H10: =IF(A10="","",Eingabe!$B$7-G10) | I10: =IF(A10="","",Eingabe!$B$8-SUMIFS($F$2:F10,$D$2:D10,D10)) | J10: =IF(A10="","",IF(E10="",1E+99,IFERROR(VLOOKUP(E10,Eingabe!$D$5:$E$44,2,FALSE),Eingabe!$B$9))) | K10: =IF(A10="","",IF(E10="",1E+99,J10-SUMIFS($F$2:F10,$E$2:E10,E10))) | L10: =IF(A10="","",IF(OR(H10<0,I10<0,K10<0),"UNMOEGLICH","OK"))
A11: =IF(ROW()-1<=Eingabe!$B$4-Eingabe!$B$3+1,Eingabe!$B$3+ROW()-2,"") | B11: =IF(A11="","",TEXT(A11,"yyyy-mm-dd")) | C11: =IF(A11="","",TEXT(A11,"ddd")) | D11: =IF(A11="","",TEXT(A11,"yyyy-mm")) | E11: =IF(A11="","",IF(A11<Eingabe!$B$5,"",INT((A11-Eingabe!$B$5)/(Eingabe!$B$6*7))+1)) | F11: =IF(A11="","",SUMPRODUCT((Eingabe!$B$16:$B$165<>"")*(Eingabe!$J$16:$J$165)*--(A11>=Eingabe!$G$16:$G$165)*--(A11<=Eingabe!$H$16:$H$165)*--(WEEKDAY(A11,2)<=5))) | G11: =IF(A11="","",SUM($F$2:F11)) | H11: =IF(A11="","",Eingabe!$B$7-G11) | I11: =IF(A11="","",Eingabe!$B$8-SUMIFS($F$2:F11,$D$2:D11,D11)) | J11: =IF(A11="","",IF(E11="",1E+99,IFERROR(VLOOKUP(E11,Eingabe!$D$5:$E$44,2,FALSE),Eingabe!$B$9))) | K11: =IF(A11="","",IF(E11="",1E+99,J11-SUMIFS($F$2:F11,$E$2:E11,E11))) | L11: =IF(A11="","",IF(OR(H11<0,I11<0,K11<0),"UNMOEGLICH","OK"))
A12: =IF(ROW()-1<=Eingabe!$B$4-Eingabe!$B$3+1,Eingabe!$B$3+ROW()-2,"") | B12: =IF(A12="","",TEXT(A12,"yyyy-mm-dd")) | C12: =IF(A12="","",TEXT(A12,"ddd")) | D12: =IF(A12="","",TEXT(A12,"yyyy-mm")) | E12: =IF(A12="","",IF(A12<Eingabe!$B$5,"",INT((A12-Eingabe!$B$5)/(Eingabe!$B$6*7))+1)) | F12: =IF(A12="","",SUMPRODUCT((Eingabe!$B$16:$B$165<>"")*(Eingabe!$J$16:$J$165)*--(A12>=Eingabe!$G$16:$G$165)*--(A12<=Eingabe!$H$16:$H$165)*--(WEEKDAY(A12,2)<=5))) | G12: =IF(A12="","",SUM($F$2:F12)) | H12: =IF(A12="","",Eingabe!$B$7-G12) | I12: =IF(A12="","",Eingabe!$B$8-SUMIFS($F$2:F12,$D$2:D12,D12)) | J12: =IF(A12="","",IF(E12="",1E+99,IFERROR(VLOOKUP(E12,Eingabe!$D$5:$E$44,2,FALSE),Eingabe!$B$9))) | K12: =IF(A12="","",IF(E12="",1E+99,J12-SUMIFS($F$2:F12,$E$2:E12,E12))) | L12: =IF(A12="","",IF(OR(H12<0,I12<0,K12<0),"UNMOEGLICH","OK"))
A13: =IF(ROW()-1<=Eingabe!$B$4-Eingabe!$B$3+1,Eingabe!$B$3+ROW()-2,"") | B13: =IF(A13="","",TEXT(A13,"yyyy-mm-dd")) | C13: =IF(A13="","",TEXT(A13,"ddd")) | D13: =IF(A13="","",TEXT(A13,"yyyy-mm")) | E13: =IF(A13="","",IF(A13<Eingabe!$B$5,"",INT((A13-Eingabe!$B$5)/(Eingabe!$B$6*7))+1)) | F13: =IF(A13="","",SUMPRODUCT((Eingabe!$B$16:$B$165<>"")*(Eingabe!$J$16:$J$165)*--(A13>=Eingabe!$G$16:$G$165)*--(A13<=Eingabe!$H$16:$H$165)*--(WEEKDAY(A13,2)<=5))) | G13: =IF(A13="","",SUM($F$2:F13)) | H13: =IF(A13="","",Eingabe!$B$7-G13) | I13: =IF(A13="","",Eingabe!$B$8-SUMIFS($F$2:F13,$D$2:D13,D13)) | J13: =IF(A13="","",IF(E13="",1E+99,IFERROR(VLOOKUP(E13,Eingabe!$D$5:$E$44,2,FALSE),Eingabe!$B$9))) | K13: =IF(A13="","",IF(E13="",1E+99,J13-SUMIFS($F$2:F13,$E$2:E13,E13))) | L13: =IF(A13="","",IF(OR(H13<0,I13<0,K13<0),"UNMOEGLICH","OK"))
... A1001: =IF(ROW()-1<=Eingabe!$B$4-Eingabe!$B$3+1,Eingabe!$B$3+ROW()-2,"") | B1001: =IF(A1001="","",TEXT(A1001,"yyyy-mm-dd")) | C1001: =IF(A1001="","",TEXT(A1001,"ddd")) | D1001: =IF(A1001="","",TEXT(A1001,"yyyy-mm")) | E1001: =IF(A1001="","",IF(A1001<Eingabe!$B$5,"",INT((A1001-Eingabe!$B$5)/(Eingabe!$B$6*7))+1)) | F1001: =IF(A1001="","",SUMPRODUCT((Eingabe!$B$16:$B$165<>"")*(Eingabe!$J$16:$J$165)*--(A1001>=Eingabe!$G$16:$G$165)*--(A1001<=Eingabe!$H$16:$H$165)*--(WEEKDAY(A1001,2)<=5))) | G1001: =IF(A1001="","",SUM($F$2:F1001)) | H1001: =IF(A1001="","",Eingabe!$B$7-G1001) | I1001: =IF(A1001="","",Eingabe!$B$8-SUMIFS($F$2:F1001,$D$2:D1001,D1001)) | J1001: =IF(A1001="","",IF(E1001="",1E+99,IFERROR(VLOOKUP(E1001,Eingabe!$D$5:$E$44,2,FALSE),Eingabe!$B$9))) | K1001: =IF(A1001="","",IF(E1001="",1E+99,J1001-SUMIFS($F$2:F1001,$E$2:E1001,E1001))) | L1001: =IF(A1001="","",IF(OR(H1001<0,I1001<0,K1001<0),"UNMOEGLICH","OK"))

Sheet Ansicht_Monat
A1: Budget/Sprint Dashboard - Monat
A2: Kalender: | B2: =TEXT(Eingabe!$B$10,"mmmm yyyy") | E2: Status Gesamt | F2: =IF(IFERROR(MATCH("UNMOEGLICH",DailyPlan!$L$2:$L$1001,0),0)=0,"OK","UNMOEGLICH")
E3: Budgetbruch ab | F3: =IFERROR(INDEX(DailyPlan!$A$2:$A$1001,MATCH("UNMOEGLICH",DailyPlan!$L$2:$L$1001,0)),"")
A4: Mo | B4: Di | C4: Mi | D4: Do | E4: Fr | F4: Sa | G4: So | I4: Details zum ausgewählten Tag
I5: Datum | J5: =Eingabe!$B$11
A6: =Eingabe!$B$10-WEEKDAY(Eingabe!$B$10,2)+1 | B6: =A6+1 | C6: =B6+1 | D6: =C6+1 | E6: =D6+1 | F6: =E6+1 | G6: =F6+1 | I6: Sprint | J6: =IFERROR(INDEX(DailyPlan!$E$2:$E$1001,MATCH($J$5,DailyPlan!$A$2:$A$1001,0)),"-")
A7: =A6+7 | B7: =A7+1 | C7: =B7+1 | D7: =C7+1 | E7: =D7+1 | F7: =E7+1 | G7: =F7+1 | I7: Geplant heute | J7: =IFERROR(INDEX(DailyPlan!$F$2:$F$1001,MATCH($J$5,DailyPlan!$A$2:$A$1001,0)),0)
A8: =A7+7 | B8: =A8+1 | C8: =B8+1 | D8: =C8+1 | E8: =D8+1 | F8: =E8+1 | G8: =F8+1 | I8: Rest Sprint | J8: =IFERROR(INDEX(DailyPlan!$K$2:$K$1001,MATCH($J$5,DailyPlan!$A$2:$A$1001,0)),0)
A9: =A8+7 | B9: =A9+1 | C9: =B9+1 | D9: =C9+1 | E9: =D9+1 | F9: =E9+1 | G9: =F9+1 | I9: Rest Monat | J9: =IFERROR(INDEX(DailyPlan!$I$2:$I$1001,MATCH($J$5,DailyPlan!$A$2:$A$1001,0)),0)
A10: =A9+7 | B10: =A10+1 | C10: =B10+1 | D10: =C10+1 | E10: =D10+1 | F10: =E10+1 | G10: =F10+1 | I10: Rest Gesamt | J10: =IFERROR(INDEX(DailyPlan!$H$2:$H$1001,MATCH($J$5,DailyPlan!$A$2:$A$1001,0)),0)
A11: =A10+7 | B11: =A11+1 | C11: =B11+1 | D11: =C11+1 | E11: =D11+1 | F11: =E11+1 | G11: =F11+1 | I11: Status | J11: =IFERROR(INDEX(DailyPlan!$L$2:$L$1001,MATCH($J$5,DailyPlan!$A$2:$A$1001,0)),"")
A13: =IF(A6="","",TEXT(A6,"d")&CHAR(10)&"Sprint "&IFERROR(INDEX(DailyPlan!$E$2:$E$1001,MATCH(A6,DailyPlan!$A$2:$A$1001,0)),"-")&CHAR(10)&TEXT(IFERROR(INDEX(DailyPlan!$F$2:$F$1001,MATCH(A6,DailyPlan!$A$2:$A$1001,0)),0),"0.0")&"h") | B13: =IF(B6="","",TEXT(B6,"d")&CHAR(10)&"Sprint "&IFERROR(INDEX(DailyPlan!$E$2:$E$1001,MATCH(B6,DailyPlan!$A$2:$A$1001,0)),"-")&CHAR(10)&TEXT(IFERROR(INDEX(DailyPlan!$F$2:$F$1001,MATCH(B6,DailyPlan!$A$2:$A$1001,0)),0),"0.0")&"h") | C13: =IF(C6="","",TEXT(C6,"d")&CHAR(10)&"Sprint "&IFERROR(INDEX(DailyPlan!$E$2:$E$1001,MATCH(C6,DailyPlan!$A$2:$A$1001,0)),"-")&CHAR(10)&TEXT(IFERROR(INDEX(DailyPlan!$F$2:$F$1001,MATCH(C6,DailyPlan!$A$2:$A$1001,0)),0),"0.0")&"h") | D13: =IF(D6="","",TEXT(D6,"d")&CHAR(10)&"Sprint "&IFERROR(INDEX(DailyPlan!$E$2:$E$1001,MATCH(D6,DailyPlan!$A$2:$A$1001,0)),"-")&CHAR(10)&TEXT(IFERROR(INDEX(DailyPlan!$F$2:$F$1001,MATCH(D6,DailyPlan!$A$2:$A$1001,0)),0),"0.0")&"h") | E13: =IF(E6="","",TEXT(E6,"d")&CHAR(10)&"Sprint "&IFERROR(INDEX(DailyPlan!$E$2:$E$1001,MATCH(E6,DailyPlan!$A$2:$A$1001,0)),"-")&CHAR(10)&TEXT(IFERROR(INDEX(DailyPlan!$F$2:$F$1001,MATCH(E6,DailyPlan!$A$2:$A$1001,0)),0),"0.0")&"h") | F13: =IF(F6="","",TEXT(F6,"d")&CHAR(10)&"Sprint "&IFERROR(INDEX(DailyPlan!$E$2:$E$1001,MATCH(F6,DailyPlan!$A$2:$A$1001,0)),"-")&CHAR(10)&TEXT(IFERROR(INDEX(DailyPlan!$F$2:$F$1001,MATCH(F6,DailyPlan!$A$2:$A$1001,0)),0),"0.0")&"h") | G13: =IF(G6="","",TEXT(G6,"d")&CHAR(10)&"Sprint "&IFERROR(INDEX(DailyPlan!$E$2:$E$1001,MATCH(G6,DailyPlan!$A$2:$A$1001,0)),"-")&CHAR(10)&TEXT(IFERROR(INDEX(DailyPlan!$F$2:$F$1001,MATCH(G6,DailyPlan!$A$2:$A$1001,0)),0),"0.0")&"h")
A14: =IF(A7="","",TEXT(A7,"d")&CHAR(10)&"Sprint "&IFERROR(INDEX(DailyPlan!$E$2:$E$1001,MATCH(A7,DailyPlan!$A$2:$A$1001,0)),"-")&CHAR(10)&TEXT(IFERROR(INDEX(DailyPlan!$F$2:$F$1001,MATCH(A7,DailyPlan!$A$2:$A$1001,0)),0),"0.0")&"h") | B14: =IF(B7="","",TEXT(B7,"d")&CHAR(10)&"Sprint "&IFERROR(INDEX(DailyPlan!$E$2:$E$1001,MATCH(B7,DailyPlan!$A$2:$A$1001,0)),"-")&CHAR(10)&TEXT(IFERROR(INDEX(DailyPlan!$F$2:$F$1001,MATCH(B7,DailyPlan!$A$2:$A$1001,0)),0),"0.0")&"h") | C14: =IF(C7="","",TEXT(C7,"d")&CHAR(10)&"Sprint "&IFERROR(INDEX(DailyPlan!$E$2:$E$1001,MATCH(C7,DailyPlan!$A$2:$A$1001,0)),"-")&CHAR(10)&TEXT(IFERROR(INDEX(DailyPlan!$F$2:$F$1001,MATCH(C7,DailyPlan!$A$2:$A$1001,0)),0),"0.0")&"h") | D14: =IF(D7="","",TEXT(D7,"d")&CHAR(10)&"Sprint "&IFERROR(INDEX(DailyPlan!$E$2:$E$1001,MATCH(D7,DailyPlan!$A$2:$A$1001,0)),"-")&CHAR(10)&TEXT(IFERROR(INDEX(DailyPlan!$F$2:$F$1001,MATCH(D7,DailyPlan!$A$2:$A$1001,0)),0),"0.0")&"h") | E14: =IF(E7="","",TEXT(E7,"d")&CHAR(10)&"Sprint "&IFERROR(INDEX(DailyPlan!$E$2:$E$1001,MATCH(E7,DailyPlan!$A$2:$A$1001,0)),"-")&CHAR(10)&TEXT(IFERROR(INDEX(DailyPlan!$F$2:$F$1001,MATCH(E7,DailyPlan!$A$2:$A$1001,0)),0),"0.0")&"h") | F14: =IF(F7="","",TEXT(F7,"d")&CHAR(10)&"Sprint "&IFERROR(INDEX(DailyPlan!$E$2:$E$1001,MATCH(F7,DailyPlan!$A$2:$A$1001,0)),"-")&CHAR(10)&TEXT(IFERROR(INDEX(DailyPlan!$F$2:$F$1001,MATCH(F7,DailyPlan!$A$2:$A$1001,0)),0),"0.0")&"h") | G14: =IF(G7="","",TEXT(G7,"d")&CHAR(10)&"Sprint "&IFERROR(INDEX(DailyPlan!$E$2:$E$1001,MATCH(G7,DailyPlan!$A$2:$A$1001,0)),"-")&CHAR(10)&TEXT(IFERROR(INDEX(DailyPlan!$F$2:$F$1001,MATCH(G7,DailyPlan!$A$2:$A$1001,0)),0),"0.0")&"h")
A15: =IF(A8="","",TEXT(A8,"d")&CHAR(10)&"Sprint "&IFERROR(INDEX(DailyPlan!$E$2:$E$1001,MATCH(A8,DailyPlan!$A$2:$A$1001,0)),"-")&CHAR(10)&TEXT(IFERROR(INDEX(DailyPlan!$F$2:$F$1001,MATCH(A8,DailyPlan!$A$2:$A$1001,0)),0),"0.0")&"h") | B15: =IF(B8="","",TEXT(B8,"d")&CHAR(10)&"Sprint "&IFERROR(INDEX(DailyPlan!$E$2:$E$1001,MATCH(B8,DailyPlan!$A$2:$A$1001,0)),"-")&CHAR(10)&TEXT(IFERROR(INDEX(DailyPlan!$F$2:$F$1001,MATCH(B8,DailyPlan!$A$2:$A$1001,0)),0),"0.0")&"h") | C15: =IF(C8="","",TEXT(C8,"d")&CHAR(10)&"Sprint "&IFERROR(INDEX(DailyPlan!$E$2:$E$1001,MATCH(C8,DailyPlan!$A$2:$A$1001,0)),"-")&CHAR(10)&TEXT(IFERROR(INDEX(DailyPlan!$F$2:$F$1001,MATCH(C8,DailyPlan!$A$2:$A$1001,0)),0),"0.0")&"h") | D15: =IF(D8="","",TEXT(D8,"d")&CHAR(10)&"Sprint "&IFERROR(INDEX(DailyPlan!$E$2:$E$1001,MATCH(D8,DailyPlan!$A$2:$A$1001,0)),"-")&CHAR(10)&TEXT(IFERROR(INDEX(DailyPlan!$F$2:$F$1001,MATCH(D8,DailyPlan!$A$2:$A$1001,0)),0),"0.0")&"h") | E15: =IF(E8="","",TEXT(E8,"d")&CHAR(10)&"Sprint "&IFERROR(INDEX(DailyPlan!$E$2:$E$1001,MATCH(E8,DailyPlan!$A$2:$A$1001,0)),"-")&CHAR(10)&TEXT(IFERROR(INDEX(DailyPlan!$F$2:$F$1001,MATCH(E8,DailyPlan!$A$2:$A$1001,0)),0),"0.0")&"h") | F15: =IF(F8="","",TEXT(F8,"d")&CHAR(10)&"Sprint "&IFERROR(INDEX(DailyPlan!$E$2:$E$1001,MATCH(F8,DailyPlan!$A$2:$A$1001,0)),"-")&CHAR(10)&TEXT(IFERROR(INDEX(DailyPlan!$F$2:$F$1001,MATCH(F8,DailyPlan!$A$2:$A$1001,0)),0),"0.0")&"h") | G15: =IF(G8="","",TEXT(G8,"d")&CHAR(10)&"Sprint "&IFERROR(INDEX(DailyPlan!$E$2:$E$1001,MATCH(G8,DailyPlan!$A$2:$A$1001,0)),"-")&CHAR(10)&TEXT(IFERROR(INDEX(DailyPlan!$F$2:$F$1001,MATCH(G8,DailyPlan!$A$2:$A$1001,0)),0),"0.0")&"h")
A16: =IF(A9="","",TEXT(A9,"d")&CHAR(10)&"Sprint "&IFERROR(INDEX(DailyPlan!$E$2:$E$1001,MATCH(A9,DailyPlan!$A$2:$A$1001,0)),"-")&CHAR(10)&TEXT(IFERROR(INDEX(DailyPlan!$F$2:$F$1001,MATCH(A9,DailyPlan!$A$2:$A$1001,0)),0),"0.0")&"h") | B16: =IF(B9="","",TEXT(B9,"d")&CHAR(10)&"Sprint "&IFERROR(INDEX(DailyPlan!$E$2:$E$1001,MATCH(B9,DailyPlan!$A$2:$A$1001,0)),"-")&CHAR(10)&TEXT(IFERROR(INDEX(DailyPlan!$F$2:$F$1001,MATCH(B9,DailyPlan!$A$2:$A$1001,0)),0),"0.0")&"h") | C16: =IF(C9="","",TEXT(C9,"d")&CHAR(10)&"Sprint "&IFERROR(INDEX(DailyPlan!$E$2:$E$1001,MATCH(C9,DailyPlan!$A$2:$A$1001,0)),"-")&CHAR(10)&TEXT(IFERROR(INDEX(DailyPlan!$F$2:$F$1001,MATCH(C9,DailyPlan!$A$2:$A$1001,0)),0),"0.0")&"h") | D16: =IF(D9="","",TEXT(D9,"d")&CHAR(10)&"Sprint "&IFERROR(INDEX(DailyPlan!$E$2:$E$1001,MATCH(D9,DailyPlan!$A$2:$A$1001,0)),"-")&CHAR(10)&TEXT(IFERROR(INDEX(DailyPlan!$F$2:$F$1001,MATCH(D9,DailyPlan!$A$2:$A$1001,0)),0),"0.0")&"h") | E16: =IF(E9="","",TEXT(E9,"d")&CHAR(10)&"Sprint "&IFERROR(INDEX(DailyPlan!$E$2:$E$1001,MATCH(E9,DailyPlan!$A$2:$A$1001,0)),"-")&CHAR(10)&TEXT(IFERROR(INDEX(DailyPlan!$F$2:$F$1001,MATCH(E9,DailyPlan!$A$2:$A$1001,0)),0),"0.0")&"h") | F16: =IF(F9="","",TEXT(F9,"d")&CHAR(10)&"Sprint "&IFERROR(INDEX(DailyPlan!$E$2:$E$1001,MATCH(F9,DailyPlan!$A$2:$A$1001,0)),"-")&CHAR(10)&TEXT(IFERROR(INDEX(DailyPlan!$F$2:$F$1001,MATCH(F9,DailyPlan!$A$2:$A$1001,0)),0),"0.0")&"h") | G16: =IF(G9="","",TEXT(G9,"d")&CHAR(10)&"Sprint "&IFERROR(INDEX(DailyPlan!$E$2:$E$1001,MATCH(G9,DailyPlan!$A$2:$A$1001,0)),"-")&CHAR(10)&TEXT(IFERROR(INDEX(DailyPlan!$F$2:$F$1001,MATCH(G9,DailyPlan!$A$2:$A$1001,0)),0),"0.0")&"h")
A17: =IF(A10="","",TEXT(A10,"d")&CHAR(10)&"Sprint "&IFERROR(INDEX(DailyPlan!$E$2:$E$1001,MATCH(A10,DailyPlan!$A$2:$A$1001,0)),"-")&CHAR(10)&TEXT(IFERROR(INDEX(DailyPlan!$F$2:$F$1001,MATCH(A10,DailyPlan!$A$2:$A$1001,0)),0),"0.0")&"h") | B17: =IF(B10="","",TEXT(B10,"d")&CHAR(10)&"Sprint "&IFERROR(INDEX(DailyPlan!$E$2:$E$1001,MATCH(B10,DailyPlan!$A$2:$A$1001,0)),"-")&CHAR(10)&TEXT(IFERROR(INDEX(DailyPlan!$F$2:$F$1001,MATCH(B10,DailyPlan!$A$2:$A$1001,0)),0),"0.0")&"h") | C17: =IF(C10="","",TEXT(C10,"d")&CHAR(10)&"Sprint "&IFERROR(INDEX(DailyPlan!$E$2:$E$1001,MATCH(C10,DailyPlan!$A$2:$A$1001,0)),"-")&CHAR(10)&TEXT(IFERROR(INDEX(DailyPlan!$F$2:$F$1001,MATCH(C10,DailyPlan!$A$2:$A$1001,0)),0),"0.0")&"h") | D17: =IF(D10="","",TEXT(D10,"d")&CHAR(10)&"Sprint "&IFERROR(INDEX(DailyPlan!$E$2:$E$1001,MATCH(D10,DailyPlan!$A$2:$A$1001,0)),"-")&CHAR(10)&TEXT(IFERROR(INDEX(DailyPlan!$F$2:$F$1001,MATCH(D10,DailyPlan!$A$2:$A$1001,0)),0),"0.0")&"h") | E17: =IF(E10="","",TEXT(E10,"d")&CHAR(10)&"Sprint "&IFERROR(INDEX(DailyPlan!$E$2:$E$1001,MATCH(E10,DailyPlan!$A$2:$A$1001,0)),"-")&CHAR(10)&TEXT(IFERROR(INDEX(DailyPlan!$F$2:$F$1001,MATCH(E10,DailyPlan!$A$2:$A$1001,0)),0),"0.0")&"h") | F17: =IF(F10="","",TEXT(F10,"d")&CHAR(10)&"Sprint "&IFERROR(INDEX(DailyPlan!$E$2:$E$1001,MATCH(F10,DailyPlan!$A$2:$A$1001,0)),"-")&CHAR(10)&TEXT(IFERROR(INDEX(DailyPlan!$F$2:$F$1001,MATCH(F10,DailyPlan!$A$2:$A$1001,0)),0),"0.0")&"h") | G17: =IF(G10="","",TEXT(G10,"d")&CHAR(10)&"Sprint "&IFERROR(INDEX(DailyPlan!$E$2:$E$1001,MATCH(G10,DailyPlan!$A$2:$A$1001,0)),"-")&CHAR(10)&TEXT(IFERROR(INDEX(DailyPlan!$F$2:$F$1001,MATCH(G10,DailyPlan!$A$2:$A$1001,0)),0),"0.0")&"h")
A18: =IF(A11="","",TEXT(A11,"d")&CHAR(10)&"Sprint "&IFERROR(INDEX(DailyPlan!$E$2:$E$1001,MATCH(A11,DailyPlan!$A$2:$A$1001,0)),"-")&CHAR(10)&TEXT(IFERROR(INDEX(DailyPlan!$F$2:$F$1001,MATCH(A11,DailyPlan!$A$2:$A$1001,0)),0),"0.0")&"h") | B18: =IF(B11="","",TEXT(B11,"d")&CHAR(10)&"Sprint "&IFERROR(INDEX(DailyPlan!$E$2:$E$1001,MATCH(B11,DailyPlan!$A$2:$A$1001,0)),"-")&CHAR(10)&TEXT(IFERROR(INDEX(DailyPlan!$F$2:$F$1001,MATCH(B11,DailyPlan!$A$2:$A$1001,0)),0),"0.0")&"h") | C18: =IF(C11="","",TEXT(C11,"d")&CHAR(10)&"Sprint "&IFERROR(INDEX(DailyPlan!$E$2:$E$1001,MATCH(C11,DailyPlan!$A$2:$A$1001,0)),"-")&CHAR(10)&TEXT(IFERROR(INDEX(DailyPlan!$F$2:$F$1001,MATCH(C11,DailyPlan!$A$2:$A$1001,0)),0),"0.0")&"h") | D18: =IF(D11="","",TEXT(D11,"d")&CHAR(10)&"Sprint "&IFERROR(INDEX(DailyPlan!$E$2:$E$1001,MATCH(D11,DailyPlan!$A$2:$A$1001,0)),"-")&CHAR(10)&TEXT(IFERROR(INDEX(DailyPlan!$F$2:$F$1001,MATCH(D11,DailyPlan!$A$2:$A$1001,0)),0),"0.0")&"h") | E18: =IF(E11="","",TEXT(E11,"d")&CHAR(10)&"Sprint "&IFERROR(INDEX(DailyPlan!$E$2:$E$1001,MATCH(E11,DailyPlan!$A$2:$A$1001,0)),"-")&CHAR(10)&TEXT(IFERROR(INDEX(DailyPlan!$F$2:$F$1001,MATCH(E11,DailyPlan!$A$2:$A$1001,0)),0),"0.0")&"h") | F18: =IF(F11="","",TEXT(F11,"d")&CHAR(10)&"Sprint "&IFERROR(INDEX(DailyPlan!$E$2:$E$1001,MATCH(F11,DailyPlan!$A$2:$A$1001,0)),"-")&CHAR(10)&TEXT(IFERROR(INDEX(DailyPlan!$F$2:$F$1001,MATCH(F11,DailyPlan!$A$2:$A$1001,0)),0),"0.0")&"h") | G18: =IF(G11="","",TEXT(G11,"d")&CHAR(10)&"Sprint "&IFERROR(INDEX(DailyPlan!$E$2:$E$1001,MATCH(G11,DailyPlan!$A$2:$A$1001,0)),"-")&CHAR(10)&TEXT(IFERROR(INDEX(DailyPlan!$F$2:$F$1001,MATCH(G11,DailyPlan!$A$2:$A$1001,0)),0),"0.0")&"h")

Sheet Ansicht_Timeline
A1: Budget/Sprint Dashboard - Timeline
A2: Projekt: | B2: =Eingabe!$B$3 | D2: =Eingabe!$B$4
A4: Woche | B4: Mo | C4: Di | D4: Mi | E4: Do | F4: Fr | G4: Sa | H4: So | J4: Monat | K4: Summe Woche (h)
A5: 1 | B5: =Eingabe!$B$3-WEEKDAY(Eingabe!$B$3,2)+1 | C5: =B5+1 | D5: =C5+1 | E5: =D5+1 | F5: =E5+1 | G5: =F5+1 | H5: =G5+1 | J5: =TEXT(B5,"mmmm yyyy") | K5: =SUMPRODUCT((DailyPlan!$A$2:$A$1001>=B5)*(DailyPlan!$A$2:$A$1001<=H5)*(DailyPlan!$F$2:$F$1001))
A6: 2 | B6: =B5+7 | C6: =B6+1 | D6: =C6+1 | E6: =D6+1 | F6: =E6+1 | G6: =F6+1 | H6: =G6+1 | J6: =TEXT(B6,"mmmm yyyy") | K6: =SUMPRODUCT((DailyPlan!$A$2:$A$1001>=B6)*(DailyPlan!$A$2:$A$1001<=H6)*(DailyPlan!$F$2:$F$1001))
A7: 3 | B7: =B6+7 | C7: =B7+1 | D7: =C7+1 | E7: =D7+1 | F7: =E7+1 | G7: =F7+1 | H7: =G7+1 | J7: =TEXT(B7,"mmmm yyyy") | K7: =SUMPRODUCT((DailyPlan!$A$2:$A$1001>=B7)*(DailyPlan!$A$2:$A$1001<=H7)*(DailyPlan!$F$2:$F$1001))
A8: 4 | B8: =B7+7 | C8: =B8+1 | D8: =C8+1 | E8: =D8+1 | F8: =E8+1 | G8: =F8+1 | H8: =G8+1 | J8: =TEXT(B8,"mmmm yyyy") | K8: =SUMPRODUCT((DailyPlan!$A$2:$A$1001>=B8)*(DailyPlan!$A$2:$A$1001<=H8)*(DailyPlan!$F$2:$F$1001))
A9: 5 | B9: =B8+7 | C9: =B9+1 | D9: =C9+1 | E9: =D9+1 | F9: =E9+1 | G9: =F9+1 | H9: =G9+1 | J9: =TEXT(B9,"mmmm yyyy") | K9: =SUMPRODUCT((DailyPlan!$A$2:$A$1001>=B9)*(DailyPlan!$A$2:$A$1001<=H9)*(DailyPlan!$F$2:$F$1001))
A10: 6 | B10: =B9+7 | C10: =B10+1 | D10: =C10+1 | E10: =D10+1 | F10: =E10+1 | G10: =F10+1 | H10: =G10+1 | J10: =TEXT(B10,"mmmm yyyy") | K10: =SUMPRODUCT((DailyPlan!$A$2:$A$1001>=B10)*(DailyPlan!$A$2:$A$1001<=H10)*(DailyPlan!$F$2:$F$1001))
A11: 7 | B11: =B10+7 | C11: =B11+1 | D11: =C11+1 | E11: =D11+1 | F11: =E11+1 | G11: =F11+1 | H11: =G11+1 | J11: =TEXT(B11,"mmmm yyyy") | K11: =SUMPRODUCT((DailyPlan!$A$2:$A$1001>=B11)*(DailyPlan!$A$2:$A$1001<=H11)*(DailyPlan!$F$2:$F$1001))
A12: 8 | B12: =B11+7 | C12: =B12+1 | D12: =C12+1 | E12: =D12+1 | F12: =E12+1 | G12: =F12+1 | H12: =G12+1 | J12: =TEXT(B12,"mmmm yyyy") | K12: =SUMPRODUCT((DailyPlan!$A$2:$A$1001>=B12)*(DailyPlan!$A$2:$A$1001<=H12)*(DailyPlan!$F$2:$F$1001))
A13: 9 | B13: =B12+7 | C13: =B13+1 | D13: =C13+1 | E13: =D13+1 | F13: =E13+1 | G13: =F13+1 | H13: =G13+1 | J13: =TEXT(B13,"mmmm yyyy") | K13: =SUMPRODUCT((DailyPlan!$A$2:$A$1001>=B13)*(DailyPlan!$A$2:$A$1001<=H13)*(DailyPlan!$F$2:$F$1001))
A14: 10 | B14: =B13+7 | C14: =B14+1 | D14: =C14+1 | E14: =D14+1 | F14: =E14+1 | G14: =F14+1 | H14: =G14+1 | J14: =TEXT(B14,"mmmm yyyy") | K14: =SUMPRODUCT((DailyPlan!$A$2:$A$1001>=B14)*(DailyPlan!$A$2:$A$1001<=H14)*(DailyPlan!$F$2:$F$1001))
A15: 11 | B15: =B14+7 | C15: =B15+1 | D15: =C15+1 | E15: =D15+1 | F15: =E15+1 | G15: =F15+1 | H15: =G15+1 | J15: =TEXT(B15,"mmmm yyyy") | K15: =SUMPRODUCT((DailyPlan!$A$2:$A$1001>=B15)*(DailyPlan!$A$2:$A$1001<=H15)*(DailyPlan!$F$2:$F$1001))
A16: 12 | B16: =B15+7 | C16: =B16+1 | D16: =C16+1 | E16: =D16+1 | F16: =E16+1 | G16: =F16+1 | H16: =G16+1 | J16: =TEXT(B16,"mmmm yyyy") | K16: =SUMPRODUCT((DailyPlan!$A$2:$A$1001>=B16)*(DailyPlan!$A$2:$A$1001<=H16)*(DailyPlan!$F$2:$F$1001))
A17: 13 | B17: =B16+7 | C17: =B17+1 | D17: =C17+1 | E17: =D17+1 | F17: =E17+1 | G17: =F17+1 | H17: =G17+1 | J17: =TEXT(B17,"mmmm yyyy") | K17: =SUMPRODUCT((DailyPlan!$A$2:$A$1001>=B17)*(DailyPlan!$A$2:$A$1001<=H17)*(DailyPlan!$F$2:$F$1001))
... A64: 60 | B64: =B63+7 | C64: =B64+1 | D64: =C64+1 | E64: =D64+1 | F64: =E64+1 | G64: =F64+1 | H64: =G64+1 | J64: =TEXT(B64,"mmmm yyyy") | K64: =SUMPRODUCT((DailyPlan!$A$2:$A$1001>=B64)*(DailyPlan!$A$2:$A$1001<=H64)*(DailyPlan!$F$2:$F$1001))

Sheet Ansicht_Balken
A1: Budget/Sprint Dashboard - Balkendiagramm
A3: Gesamt | B3: Geplant | C3: Cap | D3: Rest
A4: Projekt gesamt | B4: =SUM(DailyPlan!$F$2:$F$1001) | C4: =Eingabe!$B$7 | D4: =C4-B4
A7: Monat | B7: Geplant | C7: Cap | D7: Rest | F7: Sprint | G7: Geplant | H7: Cap | I7: Rest
A8: =TEXT(EDATE(Eingabe!$B$3,0),"yyyy-mm") | B8: =SUMIFS(DailyPlan!$F$2:$F$1001,DailyPlan!$D$2:$D$1001,A8) | C8: =Eingabe!$B$8 | D8: =C8-B8 | F8: 1 | G8: =SUMIFS(DailyPlan!$F$2:$F$1001,DailyPlan!$E$2:$E$1001,F8) | H8: =IFERROR(VLOOKUP(F8,Eingabe!$D$5:$E$44,2,FALSE),Eingabe!$B$9) | I8: =H8-G8
A9: =TEXT(EDATE(Eingabe!$B$3,1),"yyyy-mm") | B9: =SUMIFS(DailyPlan!$F$2:$F$1001,DailyPlan!$D$2:$D$1001,A9) | C9: =Eingabe!$B$8 | D9: =C9-B9 | F9: 2 | G9: =SUMIFS(DailyPlan!$F$2:$F$1001,DailyPlan!$E$2:$E$1001,F9) | H9: =IFERROR(VLOOKUP(F9,Eingabe!$D$5:$E$44,2,FALSE),Eingabe!$B$9) | I9: =H9-G9
A10: =TEXT(EDATE(Eingabe!$B$3,2),"yyyy-mm") | B10: =SUMIFS(DailyPlan!$F$2:$F$1001,DailyPlan!$D$2:$D$1001,A10) | C10: =Eingabe!$B$8 | D10: =C10-B10 | F10: 3 | G10: =SUMIFS(DailyPlan!$F$2:$F$1001,DailyPlan!$E$2:$E$1001,F10) | H10: =IFERROR(VLOOKUP(F10,Eingabe!$D$5:$E$44,2,FALSE),Eingabe!$B$9) | I10: =H10-G10
A11: =TEXT(EDATE(Eingabe!$B$3,3),"yyyy-mm") | B11: =SUMIFS(DailyPlan!$F$2:$F$1001,DailyPlan!$D$2:$D$1001,A11) | C11: =Eingabe!$B$8 | D11: =C11-B11 | F11: 4 | G11: =SUMIFS(DailyPlan!$F$2:$F$1001,DailyPlan!$E$2:$E$1001,F11) | H11: =IFERROR(VLOOKUP(F11,Eingabe!$D$5:$E$44,2,FALSE),Eingabe!$B$9) | I11: =H11-G11
A12: =TEXT(EDATE(Eingabe!$B$3,4),"yyyy-mm") | B12: =SUMIFS(DailyPlan!$F$2:$F$1001,DailyPlan!$D$2:$D$1001,A12) | C12: =Eingabe!$B$8 | D12: =C12-B12 | F12: 5 | G12: =SUMIFS(DailyPlan!$F$2:$F$1001,DailyPlan!$E$2:$E$1001,F12) | H12: =IFERROR(VLOOKUP(F12,Eingabe!$D$5:$E$44,2,FALSE),Eingabe!$B$9) | I12: =H12-G12
A13: =TEXT(EDATE(Eingabe!$B$3,5),"yyyy-mm") | B13: =SUMIFS(DailyPlan!$F$2:$F$1001,DailyPlan!$D$2:$D$1001,A13) | C13: =Eingabe!$B$8 | D13: =C13-B13 | F13: 6 | G13: =SUMIFS(DailyPlan!$F$2:$F$1001,DailyPlan!$E$2:$E$1001,F13) | H13: =IFERROR(VLOOKUP(F13,Eingabe!$D$5:$E$44,2,FALSE),Eingabe!$B$9) | I13: =H13-G13
A14: =TEXT(EDATE(Eingabe!$B$3,6),"yyyy-mm") | B14: =SUMIFS(DailyPlan!$F$2:$F$1001,DailyPlan!$D$2:$D$1001,A14) | C14: =Eingabe!$B$8 | D14: =C14-B14 | F14: 7 | G14: =SUMIFS(DailyPlan!$F$2:$F$1001,DailyPlan!$E$2:$E$1001,F14) | H14: =IFERROR(VLOOKUP(F14,Eingabe!$D$5:$E$44,2,FALSE),Eingabe!$B$9) | I14: =H14-G14
A15: =TEXT(EDATE(Eingabe!$B$3,7),"yyyy-mm") | B15: =SUMIFS(DailyPlan!$F$2:$F$1001,DailyPlan!$D$2:$D$1001,A15) | C15: =Eingabe!$B$8 | D15: =C15-B15 | F15: 8 | G15: =SUMIFS(DailyPlan!$F$2:$F$1001,DailyPlan!$E$2:$E$1001,F15) | H15: =IFERROR(VLOOKUP(F15,Eingabe!$D$5:$E$44,2,FALSE),Eingabe!$B$9) | I15: =H15-G15
A16: =TEXT(EDATE(Eingabe!$B$3,8),"yyyy-mm") | B16: =SUMIFS(DailyPlan!$F$2:$F$1001,DailyPlan!$D$2:$D$1001,A16) | C16: =Eingabe!$B$8 | D16: =C16-B16 | F16: 9 | G16: =SUMIFS(DailyPlan!$F$2:$F$1001,DailyPlan!$E$2:$E$1001,F16) | H16: =IFERROR(VLOOKUP(F16,Eingabe!$D$5:$E$44,2,FALSE),Eingabe!$B$9) | I16: =H16-G16
A17: =TEXT(EDATE(Eingabe!$B$3,9),"yyyy-mm") | B17: =SUMIFS(DailyPlan!$F$2:$F$1001,DailyPlan!$D$2:$D$1001,A17) | C17: =Eingabe!$B$8 | D17: =C17-B17 | F17: 10 | G17: =SUMIFS(DailyPlan!$F$2:$F$1001,DailyPlan!$E$2:$E$1001,F17) | H17: =IFERROR(VLOOKUP(F17,Eingabe!$D$5:$E$44,2,FALSE),Eingabe!$B$9) | I17: =H17-G17
A18: =TEXT(EDATE(Eingabe!$B$3,10),"yyyy-mm") | B18: =SUMIFS(DailyPlan!$F$2:$F$1001,DailyPlan!$D$2:$D$1001,A18) | C18: =Eingabe!$B$8 | D18: =C18-B18 | F18: 11 | G18: =SUMIFS(DailyPlan!$F$2:$F$1001,DailyPlan!$E$2:$E$1001,F18) | H18: =IFERROR(VLOOKUP(F18,Eingabe!$D$5:$E$44,2,FALSE),Eingabe!$B$9) | I18: =H18-G18
A19: =TEXT(EDATE(Eingabe!$B$3,11),"yyyy-mm") | B19: =SUMIFS(DailyPlan!$F$2:$F$1001,DailyPlan!$D$2:$D$1001,A19) | C19: =Eingabe!$B$8 | D19: =C19-B19 | F19: 12 | G19: =SUMIFS(DailyPlan!$F$2:$F$1001,DailyPlan!$E$2:$E$1001,F19) | H19: =IFERROR(VLOOKUP(F19,Eingabe!$D$5:$E$44,2,FALSE),Eingabe!$B$9) | I19: =H19-G19
A20: =TEXT(EDATE(Eingabe!$B$3,12),"yyyy-mm") | B20: =SUMIFS(DailyPlan!$F$2:$F$1001,DailyPlan!$D$2:$D$1001,A20) | C20: =Eingabe!$B$8 | D20: =C20-B20 | F20: 13 | G20: =SUMIFS(DailyPlan!$F$2:$F$1001,DailyPlan!$E$2:$E$1001,F20) | H20: =IFERROR(VLOOKUP(F20,Eingabe!$D$5:$E$44,2,FALSE),Eingabe!$B$9) | I20: =H20-G20
A21: =TEXT(EDATE(Eingabe!$B$3,13),"yyyy-mm") | B21: =SUMIFS(DailyPlan!$F$2:$F$1001,DailyPlan!$D$2:$D$1001,A21) | C21: =Eingabe!$B$8 | D21: =C21-B21 | F21: 14 | G21: =SUMIFS(DailyPlan!$F$2:$F$1001,DailyPlan!$E$2:$E$1001,F21) | H21: =IFERROR(VLOOKUP(F21,Eingabe!$D$5:$E$44,2,FALSE),Eingabe!$B$9) | I21: =H21-G21
A22: =TEXT(EDATE(Eingabe!$B$3,14),"yyyy-mm") | B22: =SUMIFS(DailyPlan!$F$2:$F$1001,DailyPlan!$D$2:$D$1001,A22) | C22: =Eingabe!$B$8 | D22: =C22-B22 | F22: 15 | G22: =SUMIFS(DailyPlan!$F$2:$F$1001,DailyPlan!$E$2:$E$1001,F22) | H22: =IFERROR(VLOOKUP(F22,Eingabe!$D$5:$E$44,2,FALSE),Eingabe!$B$9) | I22: =H22-G22
A23: =TEXT(EDATE(Eingabe!$B$3,15),"yyyy-mm") | B23: =SUMIFS(DailyPlan!$F$2:$F$1001,DailyPlan!$D$2:$D$1001,A23) | C23: =Eingabe!$B$8 | D23: =C23-B23 | F23: 16 | G23: =SUMIFS(DailyPlan!$F$2:$F$1001,DailyPlan!$E$2:$E$1001,F23) | H23: =IFERROR(VLOOKUP(F23,Eingabe!$D$5:$E$44,2,FALSE),Eingabe!$B$9) | I23: =H23-G23
A24: =TEXT(EDATE(Eingabe!$B$3,16),"yyyy-mm") | B24: =SUMIFS(DailyPlan!$F$2:$F$1001,DailyPlan!$D$2:$D$1001,A24) | C24: =Eingabe!$B$8 | D24: =C24-B24 | F24: 17 | G24: =SUMIFS(DailyPlan!$F$2:$F$1001,DailyPlan!$E$2:$E$1001,F24) | H24: =IFERROR(VLOOKUP(F24,Eingabe!$D$5:$E$44,2,FALSE),Eingabe!$B$9) | I24: =H24-G24
A25: =TEXT(EDATE(Eingabe!$B$3,17),"yyyy-mm") | B25: =SUMIFS(DailyPlan!$F$2:$F$1001,DailyPlan!$D$2:$D$1001,A25) | C25: =Eingabe!$B$8 | D25: =C25-B25 | F25: 18 | G25: =SUMIFS(DailyPlan!$F$2:$F$1001,DailyPlan!$E$2:$E$1001,F25) | H25: =IFERROR(VLOOKUP(F25,Eingabe!$D$5:$E$44,2,FALSE),Eingabe!$B$9) | I25: =H25-G25
A26: =TEXT(EDATE(Eingabe!$B$3,18),"yyyy-mm") | B26: =SUMIFS(DailyPlan!$F$2:$F$1001,DailyPlan!$D$2:$D$1001,A26) | C26: =Eingabe!$B$8 | D26: =C26-B26 | F26: 19 | G26: =SUMIFS(DailyPlan!$F$2:$F$1001,DailyPlan!$E$2:$E$1001,F26) | H26: =IFERROR(VLOOKUP(F26,Eingabe!$D$5:$E$44,2,FALSE),Eingabe!$B$9) | I26: =H26-G26
A27: =TEXT(EDATE(Eingabe!$B$3,19),"yyyy-mm") | B27: =SUMIFS(DailyPlan!$F$2:$F$1001,DailyPlan!$D$2:$D$1001,A27) | C27: =Eingabe!$B$8 | D27: =C27-B27 | F27: 20 | G27: =SUMIFS(DailyPlan!$F$2:$F$1001,DailyPlan!$E$2:$E$1001,F27) | H27: =IFERROR(VLOOKUP(F27,Eingabe!$D$5:$E$44,2,FALSE),Eingabe!$B$9) | I27: =H27-G27
A28: =TEXT(EDATE(Eingabe!$B$3,20),"yyyy-mm") | B28: =SUMIFS(DailyPlan!$F$2:$F$1001,DailyPlan!$D$2:$D$1001,A28) | C28: =Eingabe!$B$8 | D28: =C28-B28 | F28: 21 | G28: =SUMIFS(DailyPlan!$F$2:$F$1001,DailyPlan!$E$2:$E$1001,F28) | H28: =IFERROR(VLOOKUP(F28,Eingabe!$D$5:$E$44,2,FALSE),Eingabe!$B$9) | I28: =H28-G28
A29: =TEXT(EDATE(Eingabe!$B$3,21),"yyyy-mm") | B29: =SUMIFS(DailyPlan!$F$2:$F$1001,DailyPlan!$D$2:$D$1001,A29) | C29: =Eingabe!$B$8 | D29: =C29-B29 | F29: 22 | G29: =SUMIFS(DailyPlan!$F$2:$F$1001,DailyPlan!$E$2:$E$1001,F29) | H29: =IFERROR(VLOOKUP(F29,Eingabe!$D$5:$E$44,2,FALSE),Eingabe!$B$9) | I29: =H29-G29
A30: =TEXT(EDATE(Eingabe!$B$3,22),"yyyy-mm") | B30: =SUMIFS(DailyPlan!$F$2:$F$1001,DailyPlan!$D$2:$D$1001,A30) | C30: =Eingabe!$B$8 | D30: =C30-B30 | F30: 23 | G30: =SUMIFS(DailyPlan!$F$2:$F$1001,DailyPlan!$E$2:$E$1001,F30) | H30: =IFERROR(VLOOKUP(F30,Eingabe!$D$5:$E$44,2,FALSE),Eingabe!$B$9) | I30: =H30-G30
A31: =TEXT(EDATE(Eingabe!$B$3,23),"yyyy-mm") | B31: =SUMIFS(DailyPlan!$F$2:$F$1001,DailyPlan!$D$2:$D$1001,A31) | C31: =Eingabe!$B$8 | D31: =C31-B31 | F31: 24 | G31: =SUMIFS(DailyPlan!$F$2:$F$1001,DailyPlan!$E$2:$E$1001,F31) | H31: =IFERROR(VLOOKUP(F31,Eingabe!$D$5:$E$44,2,FALSE),Eingabe!$B$9) | I31: =H31-G31
F32: 25 | G32: =SUMIFS(DailyPlan!$F$2:$F$1001,DailyPlan!$E$2:$E$1001,F32) | H32: =IFERROR(VLOOKUP(F32,Eingabe!$D$5:$E$44,2,FALSE),Eingabe!$B$9) | I32: =H32-G32
F33: 26 | G33: =SUMIFS(DailyPlan!$F$2:$F$1001,DailyPlan!$E$2:$E$1001,F33) | H33: =IFERROR(VLOOKUP(F33,Eingabe!$D$5:$E$44,2,FALSE),Eingabe!$B$9) | I33: =H33-G33
F34: 27 | G34: =SUMIFS(DailyPlan!$F$2:$F$1001,DailyPlan!$E$2:$E$1001,F34) | H34: =IFERROR(VLOOKUP(F34,Eingabe!$D$5:$E$44,2,FALSE),Eingabe!$B$9) | I34: =H34-G34
F35: 28 | G35: =SUMIFS(DailyPlan!$F$2:$F$1001,DailyPlan!$E$2:$E$1001,F35) | H35: =IFERROR(VLOOKUP(F35,Eingabe!$D$5:$E$44,2,FALSE),Eingabe!$B$9) | I35: =H35-G35
F36: 29 | G36: =SUMIFS(DailyPlan!$F$2:$F$1001,DailyPlan!$E$2:$E$1001,F36) | H36: =IFERROR(VLOOKUP(F36,Eingabe!$D$5:$E$44,2,FALSE),Eingabe!$B$9) | I36: =H36-G36
F37: 30 | G37: =SUMIFS(DailyPlan!$F$2:$F$1001,DailyPlan!$E$2:$E$1001,F37) | H37: =IFERROR(VLOOKUP(F37,Eingabe!$D$5:$E$44,2,FALSE),Eingabe!$B$9) | I37: =H37-G37
F38: 31 | G38: =SUMIFS(DailyPlan!$F$2:$F$1001,DailyPlan!$E$2:$E$1001,F38) | H38: =IFERROR(VLOOKUP(F38,Eingabe!$D$5:$E$44,2,FALSE),Eingabe!$B$9) | I38: =H38-G38
F39: 32 | G39: =SUMIFS(DailyPlan!$F$2:$F$1001,DailyPlan!$E$2:$E$1001,F39) | H39: =IFERROR(VLOOKUP(F39,Eingabe!$D$5:$E$44,2,FALSE),Eingabe!$B$9) | I39: =H39-G39
F40: 33 | G40: =SUMIFS(DailyPlan!$F$2:$F$1001,DailyPlan!$E$2:$E$1001,F40) | H40: =IFERROR(VLOOKUP(F40,Eingabe!$D$5:$E$44,2,FALSE),Eingabe!$B$9) | I40: =H40-G40
F41: 34 | G41: =SUMIFS(DailyPlan!$F$2:$F$1001,DailyPlan!$E$2:$E$1001,F41) | H41: =IFERROR(VLOOKUP(F41,Eingabe!$D$5:$E$44,2,FALSE),Eingabe!$B$9) | I41: =H41-G41
F42: 35 | G42: =SUMIFS(DailyPlan!$F$2:$F$1001,DailyPlan!$E$2:$E$1001,F42) | H42: =IFERROR(VLOOKUP(F42,Eingabe!$D$5:$E$44,2,FALSE),Eingabe!$B$9) | I42: =H42-G42
F43: 36 | G43: =SUMIFS(DailyPlan!$F$2:$F$1001,DailyPlan!$E$2:$E$1001,F43) | H43: =IFERROR(VLOOKUP(F43,Eingabe!$D$5:$E$44,2,FALSE),Eingabe!$B$9) | I43: =H43-G43
...
